Workbook

Sheet P&L
A1: KSB LTD
A3: Particular | B3: 2021 | C3: =B3+1 -> 2022 | D3: =C3+1 -> 2023 | E3: =D3+1 -> 2024 | F3: =E3+1 -> 2025
A4: Income
A5: Revenue from operations | B5: 14972.91 | C5: 18219.6 | D5: 22472.38 | E5: 25330.86 | F5: 26957
A6: Other income | B6: 336.94 | C6: 421.84 | D6: 323.37 | E6: 367.51 | F6: 592
A7: Total Income | B7: 15309.85 | C7: 18641.44 | D7: 22795.75 | E7: 25698.37 | F7: 27549
A8: Expenses
A9: Cost of materials consumed | B9: 7212.55 | C9: 8942.33 | D9: 10688.97 | E9: 12034.04 | F9: 12746
A10: Purchases of stock-in-trade | B10: 1353.31 | C10: 1687.73 | D10: 1907.05 | E10: 2567.34 | F10: 2749
A11: Changes in inventories of finished goods,
A12: work-in-progress and stock-in-trade | B12: -641.61 | C12: -750.05 | D12: 179.08 | E12: -379.94 | F12: -932
A13: Employee benefits expense | B13: 2153.75 | C13: 2438.97 | D13: 2696.83 | E13: 3135.19 | F13: 3643
A14: Finance costs | B14: 50.4 | C14: 61.26 | D14: 52.9 | E14: 27.17 | F14: 30
A15: Depreciation and amortisation expense | B15: 435.34 | C15: 452.61 | D15: 496.78 | E15: 543.24 | F15: 583
A16: Other expenses | B16: 2800.24 | C16: 3434.13 | D16: 4064.75 | E16: 4598.89 | F16: 5016
A17: Total Expenses | B17: 13363.98 | C17: 16266.98 | D17: 20086.36 | E17: 22525.93 | F17: =SUM(F9:F16) -> 23835
A18: Profit before share of net profit of associate accounted
A19: for using the equity method and tax | B19: 1945.87 | C19: 2374.46 | D19: 3172.44 | E19: 2709.39 | F19: 3714
A20: Share of net profit of associate accounted for using
A21: the equity method | B21: 64.2 | C21: 78.23 | D21: 94.1 | E21: 134.06 | F21: -255
A22: Profit before tax | B22: 2010.07 | C22: 2452.69 | D22: 2803.49 | E22: 3306.5 | F22: 3459
A23: Tax expense
A24: Current tax | B24: 560.5 | C24: 538.51 | D24: 721.62 | E24: 815.07 | F24: 1007
A25: Deferred tax | B25: -44.32 | C25: 86.77 | D25: -5.46 | E25: 16.68 | F25: -107
A26: Total tax expense | B26: 516.18 | C26: 625.28 | D26: 716.16 | E26: 831.75 | F26: 900
A27: Profit for the year | B27: 1493.89 | C27: 1827.41 | D27: 2087.33 | E27: 2474.75 | F27: 2559
A28: Other comprehensive income
A29: Items that will not be reclassified to profit or loss
A30: Remeasurement of post-employment benefit obligations | B30: 8.54 | C30: -90.56 | D30: -36.73 | E30: 31.73 | F30: 0
A31: Income tax relating to items that will not be reclassified to
A32: profit or loss | B32: -2.15 | C32: 22.79 | D32: -7.98 | E32: 9.25 | F32: 0
A33: Share of Other comprehensive income of associate
A34: accounted for using the equity method | B34: -2.21 | C34: -1.76 | D34: -1.03 | E34: -3.72 | F34: =146 -> 146
A35: Total other comprehensive income for the year, net of tax | B35: 4.18 | C35: -69.53 | D35: 22.72 | E35: -31.2 | F35: -75
A36: Total comprehensive income for the year | B36: 1498.07 | C36: 1757.88 | D36: 2110.05 | E36: 2443.55 | F36: 2630
A37: Earnings per equity share
A38: Basic and Diluted (face value of ` 2/- each)

Sheet Balance Sheet
A1: KSB LTD
C3: 2021 | D3: =C3+1 -> 2022 | E3: =D3+1 -> 2023 | F3: =E3+1 -> 2024 | G3: =F3+1 -> 2025
A4: ASSETS
A5: I. | B5: Non-current assets
B6: Property, plant and equipment | C6: 2819.53 | D6: 3214.64 | E6: 3710.4 | F6: 3864.74 | G6: 4084
B7: Right-of-use assets | C7: 273.43 | D7: 269.08 | E7: 269.25 | F7: 327.18 | G7: 0
B8: Capital work-in-progress | C8: 391.76 | D8: 251.43 | E8: 310.25 | F8: 528.08 | G8: 889
B9: Other Intangible assets | C9: 13.41 | D9: 17.05 | E9: 210.24 | F9: 192.72 | G9: 192
B10: Intangible assets under development | C10: 0 | D10: 0 | E10: 13.75 | F10: 18.48 | G10: 30
B11: Financial assets
B12: (a) Investments | C12: 697.48 | D12: 741.61 | E12: 795.36 | F12: 878.28 | G12: 965
B13: (b) Trade receivables | C13: 145.36 | D13: 98.24 | E13: 42.34 | F13: 19.14 | G13: 26
B14: (c) Loans | C14: 122.27 | D14: 91.19 | E14: 73.91 | F14: 80.24 | G14: 83
B15: (d) Other financial assets | C15: 51.1 | D15: 46.33 | E15: 42.28 | F15: 77.98 | G15: 63
B16: Deferred tax Current (net) | C16: 0 | D16: 0 | E16: 0 | F16: 0 | G16: 109
B17: Assets for current tax (net) | C17: 162.57 | D17: 210.77 | E17: 185.07 | F17: 112.17 | G17: 0
B18: Other non-current assets | C18: 214.59 | D18: 569.66 | E18: 343.23 | F18: 344.18 | G18: 736
B19: Total non-current assets | C19: 4891.5 | D19: 5510 | E19: 5996.08 | F19: 6443.19 | G19: 7177
A20: II. | B20: Current assets
B21: Inventories | C21: 4230.84 | D21: 5610.89 | E21: 6426.34 | F21: 6428.23 | G21: 7861
B23: (a) Trade receivables | C23: 2779.83 | D23: 4036.53 | E23: 4917.19 | F23: 6502.73 | G23: 8692
B24: (b) Cash and cash equivalents | C24: 565.65 | D24: 319.54 | E24: 1195.28 | F24: 959.01 | G24: 1668
B25: (c) Bank balances other than (b) above | C25: 2979.65 | D25: 2290.53 | E25: 1550.4 | F25: 2275.67 | G25: 1166
B26: (d) Loans | C26: 27.08 | D26: 39.34 | E26: 27.96 | F26: 52.95 | G26: 49
B27: (e) Other financial assets | C27: 101.24 | D27: 89.94 | E27: 114.75 | F27: 116.69 | G27: 200
B28: Other current assets | C28: 517.95 | D28: 351.35 | E28: 429.43 | F28: 701.81 | G28: 1113
B29: Total current assets | C29: 11202.24 | D29: 12738.12 | E29: 14661.35 | F29: 17037.09 | G29: 20749
B30: Total Assets | C30: 16093.74 | D30: 18248.12 | E30: 20657.43 | F30: 23480.28 | G30: 27926
A31: EQUITY AND LIABILITIES
B32: EQUITY
B33: Equity share capital | C33: 348.08 | D33: 348.08 | E33: 348.08 | F33: 348.08 | G33: 348.08
B34: Other equity | C34: 9760.3 | D34: 11083.08 | E34: 12671.01 | F34: 14505.42 | G34: 16439.92
B35: Total Equity | C35: 10108.38 | D35: 11431.16 | E35: 13019.09 | F35: 14853.5 | G35: 16788
B36: LIABILITIES
B37: I. Non-current liabilities
B38: Financial liabilities
B39: (a) Lease liabilities | C39: 20.34 | D39: 19.51 | E39: 21.02 | F39: 21.67 | G39: 42
B40: Provisions | C40: 516.67 | D40: 433.1 | E40: 437 | F40: 569.82 | G40: 851
B41: Deferred tax liabilities (net) | C41: 0 | D41: 12.88 | E41: 15.4 | F41: 22.83 | G41: 0
B42: Total non-current liabilities | C42: 537.01 | D42: 465.49 | E42: 473.42 | F42: 614.32 | G42: 893
...

Sheet Scenario
A1: KSB LTD
A2: Scenario
B4: Scenario | C4: Growth(%) | F4: 2026 | G4: =F4+1 -> 2027 | H4: =G4+1 -> 2028 | I4: =H4+1 -> 2029 | J4: =I4+1 -> 2030
B5: Base Case | C5: 0.08 | F5: =C5 -> 0.08 | G5: =F5*(1-$C$8) -> 0.068 | H5: =G5*(1-$C$8) -> 0.0578 | I5: =H5*(1-$C$8) -> 0.04913 | J5: =I5*(1-$C$8) -> 0.0417605
B6: Bull Case | C6: =MAX(Model!I8:L8) -> 0.23341786 | F6: =C6 -> 0.23341786 | G6: =F6*(1-$C$8) -> 0.19840518 | H6: =G6*(1-$C$8) -> 0.1686444 | I6: =H6*(1-$C$8) -> 0.14334774 | J6: =I6*(1-$C$8) -> 0.12184558
B7: Bear Case | C7: =MIN(Model!I8:L8) -> 0.064196004 | F7: =C7 -> 0.064196004 | G7: =F7*(1-$C$8) -> 0.054566604 | H7: =G7*(1-$C$8) -> 0.046381613 | I7: =H7*(1-$C$8) -> 0.039424371 | J7: =I7*(1-$C$8) -> 0.033510716
B8: Annual Growth Tampering | C8: 0.15

Sheet C&F
A1: KSB LTD
C3: 2021 | D3: =C3+1 -> 2022 | E3: =D3+1 -> 2023 | F3: =E3+1 -> 2024 | G3: =F3+1 -> 2025
A5: A. | B5: Cash flow from operating activities
B6: Profit before tax | C6: 2010.07 | D6: 2452.69 | E6: 2803.49 | F6: 3306.5 | G6: 3459
B7: Adjustments for :
B8: Depreciation and amortisation expense | C8: 435.34 | D8: 452.61 | E8: 496.78 | F8: 543.24 | G8: 583
B9: Net (gain)/loss on disposal of property, | C9: 3.69 | D9: -13.49 | E9: -2.21 | F9: -6.32 | G9: 0
B10: plant and equipment
B11: Finance costs | C11: 50.4 | D11: 61.26 | E11: 52.9 | F11: 27.17 | G11: 30
B12: Interest income | C12: -195.76 | D12: -193.8 | E12: -163.27 | F12: -239.47 | G12: -199
B13: Fair value loss in derivative financial instruments | C13: 5.64 | D13: 3.14 | E13: -2.72 | F13: 1.4 | G13: -88
B14: Sundry credit balances and provisions
B15: no longer required, written back | C15: -3.77 | D15: -14.42 | E15: -3.45 | F15: 0 | G15: -1
B16: Unrealised foreign exchange gain | C16: -11.91 | D16: -18.93 | E16: 8.61 | F16: 4.78 | G16: 0
B17: Allowance for doubtful receivables | C17: 30.86 | D17: -41.64 | E17: -55.49 | F17: 71.89 | G17: 0
B18: Share of net profit of associates | C18: -64.2 | D18: -78.23 | E18: -94.1 | F18: -134.06 | G18: -105
C19: =SUM(C8:C18) -> 250.29 | D19: =SUM(D8:D18) -> 156.5 | E19: =SUM(E8:E18) -> 237.05 | F19: =SUM(F8:F18) -> 268.63 | G19: =SUM(G8:G18) -> 220
B20: Operating profit before working capital | C20: 2260.36 | D20: 2609.19 | E20: 3040.54 | F20: 3575.13 | G20: =G6+G19 -> 3679
B21: Adjustment for changes in working capital:
B22: (Increase) / decrease in operating assets:
B23: Inventories | C23: -622.09 | D23: -1380.05 | E23: -815.45 | F23: -1.89 | G23: -1432
B24: Trade receivables | C24: -103.69 | D24: -1138.18 | E24: -789.75 | F24: -1642.3 | G24: -2115
B25: Loans | C25: -48.73 | D25: -19.88 | E25: 28.66 | F25: -31.32 | G25: 0
B26: Other financial assets | C26: -0.62 | D26: -7.63 | E26: -46.75 | F26: -6.97 | G26: 0
B27: Other assets | C27: -256.28 | D27: 166.28 | E27: -83.95 | F27: -287.64 | G27: -423
B28: Increase / (decrease) in operating liabilities:
B29: Trade payables | C29: 183.62 | D29: 349.05 | E29: 301.28 | F29: 319.6 | G29: 722
B30: Other financial liabilities | C30: 47.76 | D30: -81.06 | E30: 110.27 | F30: 98.01 | G30: 0
B31: Other liabilities | C31: -192.03 | D31: 700.95 | E31: 295.86 | F31: 399.2 | G31: 1136
B32: Provisions | C32: 119.13 | D32: -211.94 | E32: 70.18 | F32: 117.12 | G32: 422
C33: =SUM(C23:C32) -> -872.93 | D33: =SUM(D23:D32) -> -1622.46 | E33: =SUM(E23:E32) -> -929.65 | F33: =SUM(F23:F32) -> -1036.19 | G33: =SUM(G23:G32) -> -1690
B34: Cash generated from operations | C34: 1387.43 | D34: 986.73 | E34: 2110.89 | F34: 2538.94 | G34: =G20+G33 -> 1989
B35: Income taxes paid (net of refunds) | C35: -762.57 | D35: -604.35 | E35: -695.92 | F35: -667.47 | G35: -1063
B37: Net cash flows generated from operating activities (A) | C37: 624.86 | D37: 382.38 | E37: 1414.97 | F37: 1871.47 | G37: =G34+G35 -> 926
A39: B. | B39: Cash flows from investing activities
B40: Purchase of property, plant and equipment
B41: and intangible assets | C41: -382.19 | D41: -1069.2 | E41: -932.76 | F41: -1005.5 | G41: -936
B42: Proceeds from disposal of property, plant
B43: and equipment | C43: 6.58 | D43: 15.72 | E43: 8.34 | F43: 10.67 | G43: 8
B44: Investment in fixed deposits | C44: -8411.75 | D44: -11525.43 | E44: -3098.26 | F44: -2589.2 | G44: 0
...

Sheet Model
A1: KSB LTD | F1: Historical Period | M1: Forecasting Period
A2: Financial Statement & DCF Analysis | H2: 2021 | I2: =H2+1 -> 2022 | J2: =I2+1 -> 2023 | K2: =J2+1 -> 2024 | L2: =K2+1 -> 2025 | M2: =L2+1 -> 2026 | N2: =M2+1 -> 2027 | O2: =N2+1 -> 2028 | P2: =O2+1 -> 2029 | Q2: =P2+1 -> 2030
D3: Master check | H3: =IF(H73>1,"Error","OK") -> OK | I3: =IF(I73>1,"Error","OK") -> OK | J3: =IF(J73>1,"Error","OK") -> OK | K3: =IF(K73>1,"Error","OK") -> OK | L3: =IF(L73>1,"Error","OK") -> OK | M3: =IF(M73>1,"Error","OK") -> OK | N3: =IF(N73>1,"Error","OK") -> OK | O3: =IF(O73>1,"Error","OK") -> OK | ... Q3: =IF(Q73>1,"Error","OK") -> OK
A5: Ratio & Assumptions
D7: Scenario | E7: Base Case | F7: Units | G7: =IF(E7=Scenario!B5,1,IF(Model!E7=Scenario!B6,2,3)) -> 1
D8: Revenue Growth Rate | F8: % | H8: N/A | I8: =I25/H25-1 -> 0.21683761 | J8: =J25/I25-1 -> 0.23341786 | K8: =K25/J25-1 -> 0.1271997 | L8: =L25/K25-1 -> 0.064196004 | M8: {=CHOOSE(G7,Scenario!F5:J5,Scenario!F6:J6,Scenario!F7:J7)} -> 0.08 | N8: 0.068 | O8: 0.0578 | P8: 0.04913 | Q8: 0.0417605
D9: COGS (% of Revenue) | F9: % | H9: =-(H26/H25) -> 0.52923914 | I9: =-(I26/I25) -> 0.54227371 | J9: =-(J26/J25) -> 0.56848006 | K9: =-(K26/K25) -> 0.56142744 | L9: =-(L26/L25) -> 0.54023074 | M9: =AVERAGE(H9:L9) -> 0.54833022 | N9: =M9 -> 0.54833022 | O9: =N9 -> 0.54833022 | P9: =O9 -> 0.54833022 | Q9: =P9 -> 0.54833022
D10: Salary (% of Revenue) | F10: % | H10: =-(H29/H25) -> 0.14384311 | I10: =-(I29/I25) -> 0.13386518 | J10: =-(J29/J25) -> 0.12000643 | K10: =-(K29/K25) -> 0.12376958 | L10: =-(L29/L25) -> 0.13514115 | M10: =AVERAGE(H10:L10) -> 0.13132509 | N10: =M10 -> 0.13132509 | O10: =N10 -> 0.13132509 | P10: =O10 -> 0.13132509 | Q10: =P10 -> 0.13132509
D11: Other SG&A (% of Revenue) | F11: % | H11: =-H30/H25 -> 0.18702043 | I11: =-I30/I25 -> 0.18848548 | J11: =-J30/J25 -> 0.18087759 | K11: =-K30/K25 -> 0.18155286 | L11: =-L30/L25 -> 0.18607412 | M11: =AVERAGE(H11:L11) -> 0.18480209 | N11: =M11 -> 0.18480209 | O11: =N11 -> 0.18480209 | P11: =O11 -> 0.18480209 | Q11: =P11 -> 0.18480209
D12: Depreciation & Amortization (% of PPE) | F12: % | I12: =-I32/I118 -> 0.12938627 | J12: =-J32/J118 -> 0.13239699 | K12: =-K32/K118 -> 0.12034852 | L12: =-L32/L118 -> 0.1182268 | M12: =AVERAGE(H12:L12) -> 0.12508965 | N12: =M12 -> 0.12508965 | O12: =N12 -> 0.12508965 | P12: =O12 -> 0.12508965 | Q12: =P12 -> 0.12508965
D13: Interest (% of debt) | F13: % | I13: =-I34/I124 -> 2.0495149 | J13: =-J34/J124 -> 1.8355309 | K13: =-K34/K124 -> 0.83961681 | L13: =-L34/L124 -> 0.87310827 | M13: 0.07 | N13: 0.07 | O13: 0.07 | P13: 0.07 | Q13: 0.07
D14: Other Income (Expenses)(% of Revenue) | F14: % | H14: =H35/H25 -> 0.026791051 | I14: =I35/I25 -> 0.027446816 | J14: =J35/J25 -> 0.018577027 | K14: =K35/K25 -> 0.019800749 | L14: =L35/L25 -> 0.012501391 | M14: =AVERAGE(H14:L14) -> 0.021023407 | N14: =M14 -> 0.021023407 | O14: =N14 -> 0.021023407 | P14: =O14 -> 0.021023407 | Q14: =P14 -> 0.021023407
D15: Taxes Rate (% of Earning Before Tax) | F15: % | H15: =-H37/H36 -> 0.25679703 | I15: =-I37/I36 -> 0.25493642 | J15: =-J37/J36 -> 0.25545302 | K15: =-K37/K36 -> 0.25154998 | L15: =-L37/L36 -> 0.26019081 | M15: =AVERAGE(H15:L15) -> 0.25578545 | N15: =M15 -> 0.25578545 | O15: =N15 -> 0.25578545 | P15: =O15 -> 0.25578545 | Q15: =P15 -> 0.25578545
D16: Divident Payout Ratio | F16: % | H16: =-H98/H38 -> 0.1980534 | I16: =-I98/I38 -> 0.23809654 | J16: =-J98/J38 -> 0.25013774 | K16: =-K98/K38 -> 0.24614203 | L16: =-L98/L38 -> 0.27198124 | M16: =AVERAGE(H16:L16) -> 0.24088219 | N16: =M16 -> 0.24088219 | O16: =N16 -> 0.24088219 | P16: =O16 -> 0.24088219 | Q16: =P16 -> 0.24088219
D17: Account Recievable | F17: Days | H17: =H47/H25*365 -> 67.764913 | I17: =I47/I25*365 -> 80.865302 | J17: =J47/J25*365 -> 79.865789 | K17: =K47/K25*365 -> 93.699797 | L17: =L47/L25*365 -> 117.6904 | M17: 110 | N17: 105 | O17: 100 | P17: 96 | Q17: 93
D18: Inventory | F18: Days | H18: =-H48/H26*365 -> 194.87732 | I18: =-I48/I26*365 -> 207.28469 | J18: =-J48/J26*365 -> 183.60828 | K18: =-K48/K26*365 -> 164.98357 | L18: =-L48/L26*365 -> 197.02431 | M18: =AVERAGE(H18:L18) -> 189.55563 | N18: =M18 -> 189.55563 | O18: =N18 -> 189.55563 | P18: =O18 -> 189.55563 | Q18: =P18 -> 189.55563
D19: Account Payable | F19: Days | H19: =-H60/H26*365 -> 128.58198 | I19: =-I60/I26*365 -> 116.10055 | J19: =-J60/J26*365 -> 98.072089 | K19: =-K60/K26*365 -> 96.332534 | L19: =-L60/L26*365 -> 110.6053 | M19: =AVERAGE(H19:L19) -> 109.93849 | N19: =M19 -> 109.93849 | O19: =N19 -> 109.93849 | P19: =O19 -> 109.93849 | Q19: =P19 -> 109.93849
D20: Capital Asset Turnover Ratio | F20: Times | H20: =H25/H52 -> 4.2802612 | I20: =I25/I52 -> 4.8557113 | J20: =J25/J52 -> 4.9784953 | K20: =K25/K52 -> 5.1368551 | L20: =L25/L52 -> 5.1890279 | M20: =L20+0.02 -> 5.2090279 | N20: =M20+0.02 -> 5.2290279 | O20: =N20+0.02 -> 5.2490279 | P20: =O20+0.02 -> 5.2690279 | Q20: =P20+0.02 -> 5.2890279
A23: Income Statement
B24: Income
D25: Revenue | F25: ₹ in MM | H25: ='P&L'!B5 -> 14972.91 | I25: ='P&L'!C5 -> 18219.6 | J25: ='P&L'!D5 -> 22472.38 | K25: ='P&L'!E5 -> 25330.86 | L25: ='P&L'!F5 -> 26957 | M25: =L25*(1+M8) -> 29113.56 | N25: =M25*(1+N8) -> 31093.282 | O25: =N25*(1+O8) -> 32890.474 | P25: =O25*(1+P8) -> 34506.383 | Q25: =P25*(1+Q8) -> 35947.387
D26: Cost of Good Solds (COGS) | F26: ₹ in MM | H26: =-('P&L'!B9+'P&L'!B10+'P&L'!B12) -> -7924.25 | I26: =-('P&L'!C9+'P&L'!C10+'P&L'!C12) -> -9880.01 | J26: =-('P&L'!D9+'P&L'!D10+'P&L'!D12) -> -12775.1 | K26: =-('P&L'!E9+'P&L'!E10+'P&L'!E12) -> -14221.44 | L26: =-('P&L'!F9+'P&L'!F10+'P&L'!F12) -> -14563 | M26: =-M25*M9 -> -15963.845 | N26: =-N25*N9 -> -17049.386 | O26: =-O25*O9 -> -18034.841 | P26: =-P25*P9 -> -18920.892 | Q26: =-Q25*Q9 -> -19711.038
D27: Gross Profit | F27: ₹ in MM | H27: =SUM(H25:H26) -> 7048.66 | I27: =SUM(I25:I26) -> 8339.59 | J27: =SUM(J25:J26) -> 9697.28 | K27: =SUM(K25:K26) -> 11109.42 | L27: =SUM(L25:L26) -> 12394 | M27: =SUM(M25:M26) -> 13149.715 | N27: =SUM(N25:N26) -> 14043.896 | O27: =SUM(O25:O26) -> 14855.633 | ... Q27: =SUM(Q25:Q26) -> 16236.348
B28: Expenses
D29: Salaries & Benefits | F29: ₹ in MM | H29: =-'P&L'!B13 -> -2153.75 | I29: =-'P&L'!C13 -> -2438.97 | J29: =-'P&L'!D13 -> -2696.83 | K29: =-'P&L'!E13 -> -3135.19 | L29: =-'P&L'!F13 -> -3643 | M29: =-M25*M10 -> -3823.3409 | N29: =-N25*N10 -> -4083.3281 | O29: =-O25*O10 -> -4319.3444 | P29: =-P25*P10 -> -4531.5538 | Q29: =-Q25*Q10 -> -4720.7938
D30: Other SG&A Expenses | F30: ₹ in MM | H30: =-'P&L'!B16 -> -2800.24 | I30: =-'P&L'!C16 -> -3434.13 | J30: =-'P&L'!D16 -> -4064.75 | K30: =-'P&L'!E16 -> -4598.89 | L30: =-'P&L'!F16 -> -5016 | M30: =-(M25*M11) -> -5380.2469 | N30: =-(N25*N11) -> -5746.1036 | O30: =-(O25*O11) -> -6078.2284 | P30: =-(P25*P11) -> -6376.8518 | Q30: =-(Q25*Q11) -> -6643.1523
D31: EBITDA | F31: ₹ in MM | H31: =SUM(H27:H30) -> 2094.67 | I31: =SUM(I27:I30) -> 2466.49 | J31: =SUM(J27:J30) -> 2935.7 | K31: =SUM(K27:K30) -> 3375.34 | L31: =SUM(L27:L30) -> 3735 | M31: =SUM(M27:M30) -> 3946.1275 | N31: =SUM(N27:N30) -> 4214.4642 | O31: =SUM(O27:O30) -> 4458.0602 | ... Q31: =SUM(Q27:Q30) -> 4872.4021
D32: Depreciation & Amortization Expenses | F32: ₹ in MM | H32: =-'P&L'!B15 -> -435.34 | I32: =-'P&L'!C15 -> -452.61 | J32: =-'P&L'!D15 -> -496.78 | K32: =-'P&L'!E15 -> -543.24 | L32: =-'P&L'!F15 -> -583 | M32: =M120 -> -649.84072 | N32: =N120 -> -620.34003 | O32: =O120 -> -590.10114 | P32: =P120 -> -559.11449 | Q32: =Q120 -> -527.53764
D33: EBIT | F33: ₹ in MM | H33: =SUM(H31:H32) -> 1659.33 | I33: =SUM(I31:I32) -> 2013.88 | J33: =SUM(J31:J32) -> 2438.92 | K33: =SUM(K31:K32) -> 2832.1 | L33: =SUM(L31:L32) -> 3152 | M33: =SUM(M31:M32) -> 3296.2868 | N33: =SUM(N31:N32) -> 3594.1242 | O33: =SUM(O31:O32) -> 3867.9591 | ... Q33: =SUM(Q31:Q32) -> 4344.8645
D34: Interest | F34: ₹ in MM | H34: =-'P&L'!B14 -> -50.4 | I34: =-'P&L'!C14 -> -61.26 | J34: =-'P&L'!D14 -> -52.9 | K34: =-'P&L'!E14 -> -27.17 | L34: =-'P&L'!F14 -> -30 | M34: =M127 -> -2.94 | N34: =N127 -> -2.94 | O34: =O127 -> -2.94 | P34: =P127 -> -2.94 | Q34: =Q127 -> -2.94
D35: Other Income (Expenses) | F35: ₹ in MM | H35: ='P&L'!B6+'P&L'!B21 -> 401.14 | I35: ='P&L'!C6+'P&L'!C21 -> 500.07 | J35: ='P&L'!D6+'P&L'!D21 -> 417.47 | K35: ='P&L'!E6+'P&L'!E21 -> 501.57 | L35: ='P&L'!F6+'P&L'!F21 -> 337 | M35: =M25*M14 -> 612.06621 | N35: =N25*N14 -> 653.68671 | O35: =O25*O14 -> 691.46981 | P35: =P25*P14 -> 725.44172 | Q35: =Q25*Q14 -> 755.73653
D36: Earning Before Tax | F36: ₹ in MM | H36: =SUM(H33:H35) -> 2010.07 | I36: =SUM(I33:I35) -> 2452.69 | J36: =SUM(J33:J35) -> 2803.49 | K36: =SUM(K33:K35) -> 3306.5 | L36: =SUM(L33:L35) -> 3459 | M36: =SUM(M33:M35) -> 3905.413 | N36: =SUM(N33:N35) -> 4244.8709 | O36: =SUM(O33:O35) -> 4556.4889 | ... Q36: =SUM(Q33:Q35) -> 5097.661
D37: Taxes | F37: ₹ in MM | H37: =-'P&L'!B26 -> -516.18 | I37: =-'P&L'!C26 -> -625.28 | J37: =-'P&L'!D26 -> -716.16 | K37: =-'P&L'!E26 -> -831.75 | L37: =-'P&L'!F26 -> -900 | M37: =-M36*M15 -> -998.94783 | N37: =-N36*N15 -> -1085.7762 | O37: =-O36*O15 -> -1165.4836 | P37: =-P36*P15 -> -1238.1223 | Q37: =-Q36*Q15 -> -1303.9075
D38: Net Earing | F38: ₹ in MM | H38: =SUM(H36:H37) -> 1493.89 | I38: =SUM(I36:I37) -> 1827.41 | J38: =SUM(J36:J37) -> 2087.33 | K38: =SUM(K36:K37) -> 2474.75 | L38: =SUM(L36:L37) -> 2559 | M38: =SUM(M36:M37) -> 2906.4652 | N38: =SUM(N36:N37) -> 3159.0947 | O38: =SUM(O36:O37) -> 3391.0053 | ... Q38: =SUM(Q36:Q37) -> 3793.7535
A41: Balance Sheet
B43: Asset
C44: Current Asset :
D45: Cash | F45: ₹ in MM | H45: ='Balance Sheet'!C24 -> 565.65 | I45: ='Balance Sheet'!D24 -> 319.54 | J45: ='Balance Sheet'!E24 -> 1195.28 | K45: ='Balance Sheet'!F24 -> 959.01 | L45: ='Balance Sheet'!G24 -> 1668 | M45: =M71-(M46+M47+M48+M49+M52+M53+M54+M55) -> 4261.1763 | N45: =N71-(N46+N47+N48+N49+N52+N53+N54+N55) -> 6738.7737 | O45: =O71-(O46+O47+O48+O49+O52+O53+O54+O55) -> 9501.8667 | P45: =P71-(P46+P47+P48+P49+P52+P53+P54+P55) -> 12431.225 | Q45: =Q71-(Q46+Q47+Q48+Q49+Q52+Q53+Q54+Q55) -> 15488.806
D46: Bank Deposits | F46: ₹ in MM | H46: ='Balance Sheet'!C25 -> 2979.65 | I46: ='Balance Sheet'!D25 -> 2290.53 | J46: ='Balance Sheet'!E25 -> 1550.4 | K46: ='Balance Sheet'!F25 -> 2275.67 | L46: ='Balance Sheet'!G25 -> 1166 | M46: =L46 -> 1166 | N46: =M46 -> 1166 | O46: =N46 -> 1166 | P46: =O46 -> 1166 | Q46: =P46 -> 1166
D47: Account Receivable | F47: ₹ in MM | H47: ='Balance Sheet'!C23 -> 2779.83 | I47: ='Balance Sheet'!D23 -> 4036.53 | J47: ='Balance Sheet'!E23 -> 4917.19 | K47: ='Balance Sheet'!F23 -> 6502.73 | L47: ='Balance Sheet'!G23 -> 8692 | M47: =M25*M17/365 -> 8773.9496 | N47: =N25*N17/365 -> 8944.6428 | O47: =O25*O17/365 -> 9011.0887 | P47: =P25*P17/365 -> 9075.6514 | Q47: =Q25*Q17/365 -> 9159.1971
...

Sheet DCF
A1: KSB LIMITED — DCF VALUATION MODEL (FCFF Method) | INR Millions
A2: Scenario-linked via dropdown (E5) → CHOOSE pulls from Scenario sheet | Yellow=Input | Base/Bull/Bear
A4: SCENARIO SELECTOR
A5: ► Select Scenario : | D5: Base Case | E5: =IF(D5="Base Case",1,IF(D5="Bull Case",2,3)) -> 1 | F5: =IF(D5="Base Case","Rev CAGR ~8% | Base ops",IF(D5="Bull Case","Rev CAGR ~23% | Nuclear ramp + peak cycle","Rev CAGR ~6.4% | Muted cycle")) -> Rev CAGR ~8% | Base ops
A6: Revenue Growth (Scenario-linked): | G6: =CHOOSE(E5,Scenario!F5,Scenario!F6,Scenario!F7) -> 0.08 | H6: =CHOOSE(E5,Scenario!G5,Scenario!G6,Scenario!G7) -> 0.068 | I6: =CHOOSE(E5,Scenario!H5,Scenario!H6,Scenario!H7) -> 0.0578 | J6: =CHOOSE(E5,Scenario!I5,Scenario!I6,Scenario!I7) -> 0.04913 | K6: =CHOOSE(E5,Scenario!J5,Scenario!J6,Scenario!J7) -> 0.0417605
A8: KEY ASSUMPTIONS
A9: Parameter | D9: Value | E9: Notes
A10: WACC | D10: 0.1163 | E10: From WACC sheet — Ke=12.18%, Kd=5.63%, We=99.75%
A11: Tax Rate | D11: 0.25 | E11: Effective rate consistent with FY2025 actuals
A12: EV/EBITDA Exit Multiple | D12: 15 | E12: Conservative vs peer median 25x | KSB trades 36x
A13: Terminal Growth Rate (g) | D13: 0.04 | E13: Long-term nominal GDP proxy = 4%
A14: Shares Outstanding (Crores) | D14: 17.4 | E14: FV ₹2 | Source: BSE
A15: Net Cash FY2025 (₹ MM) | D15: 18298 | E15: Cash+FDs 18,340 − Lease Liab 42 = 18,298
A16: Current Market Price (₹) | D16: 972 | E16: NSE price Apr 2026
A18: INCOME STATEMENT PROJECTIONS
A19: Line Item | C19: Units | D19: FY2025A | E19: FY2026E | F19: FY2027E | G19: FY2028E | H19: FY2029E | I19: FY2030E
A20: Revenue | C20: ₹ MM | D20: =Model!L25 -> 26957 | E20: =D20*(1+G6) -> 29113.56 | F20: =E20*(1+H6) -> 31093.282 | G20: =F20*(1+I6) -> 32890.474 | H20: =G20*(1+J6) -> 34506.383 | I20: =H20*(1+K6) -> 35947.387
A21: Revenue Growth % | C21: % | D21: — | E21: =E20/D20-1 -> 0.08 | F21: =F20/E20-1 -> 0.068 | G21: =G20/F20-1 -> 0.0578 | H21: =H20/G20-1 -> 0.04913 | I21: =I20/H20-1 -> 0.0417605
A22: COGS | C22: ₹ MM | D22: =Model!L26 -> -14563 | E22: =-E20*Model!L9 -> -15728.04 | F22: =-F20*Model!L9 -> -16797.547 | G22: =-G20*Model!L9 -> -17768.445 | H22: =-H20*Model!L9 -> -18641.409 | I22: =-I20*Model!L9 -> -19419.883
A23: Salaries | C23: ₹ MM | D23: =Model!L29 -> -3643 | E23: =-E20*Model!L10 -> -3934.44 | F23: =-F20*Model!L10 -> -4201.9819 | G23: =-G20*Model!L10 -> -4444.8565 | H23: =-H20*Model!L10 -> -4663.2323 | I23: =-I20*Model!L10 -> -4857.9712
A24: Other SG&A | C24: ₹ MM | D24: =Model!L30 -> -5016 | E24: =-E20*Model!L11 -> -5417.28 | F24: =-F20*Model!L11 -> -5785.655 | G24: =-G20*Model!L11 -> -6120.0659 | H24: =-H20*Model!L11 -> -6420.7447 | I24: =-I20*Model!L11 -> -6688.8782
A25: EBITDA | C25: ₹ MM | D25: =D20+D22+D23+D24 -> 3735 | E25: =D20+D22+D23+D24 -> 3735 | F25: =E20+E22+E23+E24 -> 4033.8 | G25: =F20+F22+F23+F24 -> 4308.0984 | H25: =G20+G22+G23+G24 -> 4557.1065 | I25: =H20+H22+H23+H24 -> 4780.9971
A26: EBITDA Margin | C26: % | D26: =D25/D20 -> 0.13855399 | E26: =E25/E20 -> 0.12829073 | F26: =F25/F20 -> 0.1297322 | G26: =G25/G20 -> 0.13098317 | H26: =H25/H20 -> 0.13206561 | I26: =I25/I20 -> 0.13299985
A27: D&A | C27: ₹ MM | D27: =Model!L32 -> -583 | E27: =-D20*Model!L12 -> -3187.0399 | F27: =-E20*Model!L12 -> -3442.0031 | G27: =-F20*Model!L12 -> -3676.0593 | H27: =-G20*Model!L12 -> -3888.5355 | I27: =-H20*Model!L12 -> -4079.5792
A28: EBIT | C28: ₹ MM | D28: =D25+D27 -> 3152 | E28: =D25+D27 -> 3152 | F28: =E25+E27 -> 547.96013 | G28: =F25+F27 -> 591.79694 | H28: =G25+G27 -> 632.03913 | I28: =H25+H27 -> 668.571
A29: EBIT Margin | C29: % | D29: =D28/D20 -> 0.11692696 | E29: =E28/E20 -> 0.1082657 | F29: =F28/F20 -> 0.017623104 | G29: =G28/G20 -> 0.017992959 | H29: =H28/H20 -> 0.018316586 | I29: =I28/I20 -> 0.018598598
A30: Interest | C30: ₹ MM | D30: =Model!L34 -> -30 | E30: =Model!L34 -> -30 | F30: =Model!M34 -> -2.94 | G30: =Model!N34 -> -2.94 | H30: =Model!O34 -> -2.94 | I30: =Model!P34 -> -2.94
A31: Other Income | C31: ₹ MM | D31: =Model!L35 -> 337 | E31: =E20*Model!L14 -> 363.96 | F31: =F20*Model!L14 -> 388.70928 | G31: =G20*Model!L14 -> 411.17668 | H31: =H20*Model!L14 -> 431.37779 | I31: =I20*Model!L14 -> 449.39234
A32: PBT | C32: ₹ MM | D32: =D28+D30+D31 -> 3459 | E32: =D28+D30+D31 -> 3459 | F32: =E28+E30+E31 -> 3485.96 | G32: =F28+F30+F31 -> 933.72941 | H32: =G28+G30+G31 -> 1000.0336 | I32: =H28+H30+H31 -> 1060.4769
A33: Tax | C33: ₹ MM | D33: =Model!L37 -> -900 | E33: =-E32*D11 -> -864.75 | F33: =-F32*D11 -> -871.49 | G33: =-G32*D11 -> -233.43235 | H33: =-H32*D11 -> -250.0084 | I33: =-I32*D11 -> -265.11923
A34: Net Earning | C34: ₹ MM | D34: =D32+D33 -> 2559 | E34: =D32+D33 -> 2559 | F34: =E32+E33 -> 2594.25 | G34: =F32+F33 -> 2614.47 | H34: =G32+G33 -> 700.29706 | I34: =H32+H33 -> 750.02521
A35: Net Margin | C35: % | D35: =D34/D20 -> 0.094928961 | E35: =E34/E20 -> 0.087897186 | F35: =F34/F20 -> 0.083434421 | G35: =G34/G20 -> 0.07949019 | H35: =H34/H20 -> 0.020294711 | I35: =I34/I20 -> 0.020864527
A36: EPS (FV ₹2) | C36: ₹ MM | D36: =D34/(D14*10) -> 14.706897 | E36: =D34/(D14*10) -> 14.706897 | F36: =E34/(D14*10) -> 14.706897 | G36: =F34/(D14*10) -> 14.909483 | H36: =G34/(D14*10) -> 15.02569 | I36: =H34/(D14*10) -> 4.0246957
A38: FREE CASH FLOW TO FIRM (FCFF)
A39: Line Item | C39: Units | D39: FY2026E | E39: FY2027E | F39: FY2028E | G39: FY2029E | H39: FY2030E
A40: EBIT | C40: ₹ MM | D40: =E28 -> 3152 | E40: =F28 -> 547.96013 | F40: =G28 -> 591.79694 | G40: =H28 -> 632.03913 | H40: =I28 -> 668.571 | I40: =H28 -> 632.03913
A41: Less: Cash Tax on EBIT | C41: ₹ MM | D41: =-D40*D11 -> -788 | E41: =-E40*D11 -> -136.99003 | F41: =-F40*D11 -> -147.94924 | G41: =-G40*D11 -> -158.00978 | H41: =-H40*D11 -> -167.14275 | I41: =-H40*D11 -> -167.14275
A42: NOPAT | C42: ₹ MM | D42: =D40+D41 -> 2364 | E42: =E40+E41 -> 410.9701 | F42: =F40+F41 -> 443.84771 | G42: =G40+G41 -> 474.02935 | H42: =H40+H41 -> 501.42825 | I42: =H40+H41 -> 501.42825
A43: Add: D&A | C43: ₹ MM | D43: =-E27 -> 3187.0399 | E43: =-F27 -> 3442.0031 | F43: =-G27 -> 3676.0593 | G43: =-H27 -> 3888.5355 | H43: =-I27 -> 4079.5792 | I43: =-H27 -> 3888.5355
A44: Less: Capex | C44: ₹ MM | D44: =Model!M121 -> 4959.1636 | E44: =Model!N121 -> 4717.4259 | F44: =Model!O121 -> 4469.7104 | G44: =Model!P121 -> 4217.2765 | H44: =Model!Q121 -> 3962.1904 | I44: =Model!Q121 -> 3962.1904
...

Sheet Comp Valuation
A1: KSB LTD
A2: Comp Valuation
E4: Market Data | M4: Financial Data | Q4: Valuation
E5: Ticker | F5: Price | G5: Shares | H5: Market Cap | I5: Debt | J5: Cash | K5: EV | M5: Sales | N5: EBITDA | O5: Earning | Q5: Ev/Sale | R5: Ev/EBITDA | S5: P/E
D6: Company | F6: (₹/Share) | G6: M | H6: ₹ MM | I6: ₹ MM | J6: ₹ MM | K6: ₹ MM | M6: ₹ MM | N6: ₹ MM | O6: ₹ MM | Q6: x | R6: x | S6: x
D8: Kirloskar Brothers Ltd | E8: KIRLOSBROS | F8: 1775 | G8: 58 | H8: =F8*G8 -> 102950 | I8: 2850 | J8: 8200 | K8: =H8+I8-J8 -> 97600 | M8: 44922 | N8: 5100 | O8: 4151 | Q8: =K8/M8 -> 2.1726548 | R8: =K8/N8 -> 19.137255 | S8: =H8/O8 -> 24.801253
D9: Elgi Equipments Ltd | E9: ELGIEQUIP | F9: 580 | G9: 315 | H9: =F9*G9 -> 182700 | I9: 1200 | J9: 12500 | K9: =H9+I9-J9 -> 171400 | M9: 35105 | N9: 5827 | O9: 3447 | Q9: =K9/M9 -> 4.8824954 | R9: =K9/N9 -> 29.414793 | S9: =H9/O9 -> 53.002611
D10: Cummins India Ltd | E10: CUMMINSI | F10: 2510 | G10: 277 | H10: =F10*G10 -> 695270 | I10: 2100 | J10: 28000 | K10: =H10+I10-J10 -> 669370 | M10: 89520 | N10: 16800 | O10: 12500 | Q10: =K10/M10 -> 7.4773235 | R10: =K10/N10 -> 39.843452 | S10: =H10/O10 -> 55.6216
D11: Triveni Turbine Ltd | E11: TRITURBINE | F11: 620 | G11: 330 | H11: =F11*G11 -> 204600 | I11: 800 | J11: 6500 | K11: =H11+I11-J11 -> 198900 | M11: 20400 | N11: 4200 | O11: 3420 | Q11: =K11/M11 -> 9.75 | R11: =K11/N11 -> 47.357143 | S11: =H11/O11 -> 59.824561
D12: Ingersoll Rand India | E12: INGERRAN | F12: 3800 | G12: 29 | H12: =F12*G12 -> 110200 | I12: 0 | J12: 8500 | K12: =H12+I12-J12 -> 101700 | M12: 13250 | N12: 3100 | O12: 2350 | Q12: =K12/M12 -> 7.6754717 | R12: =K12/N12 -> 32.806452 | S12: =H12/O12 -> 46.893617
D13: Shakti Pumps India Ltd | E13: SHAKTIPU | F13: 1050 | G13: 27 | H13: =F13*G13 -> 28350 | I13: 3200 | J13: 2800 | K13: =H13+I13-J13 -> 28750 | M13: 9840 | N13: 1950 | O13: 1420 | Q13: =K13/M13 -> 2.921748 | R13: =K13/N13 -> 14.74359 | S13: =H13/O13 -> 19.964789
D14: WPIL Ltd | E14: WPIL | F14: 570 | G14: 14 | H14: =F14*G14 -> 7980 | I14: 1800 | J14: 1200 | K14: =H14+I14-J14 -> 8580 | M14: 5830 | N14: 870 | O14: 620 | Q14: =K14/M14 -> 1.4716981 | R14: =K14/N14 -> 9.862069 | S14: =H14/O14 -> 12.870968
D15: Roto Pumps Ltd | E15: ROTOPUMP | F15: 460 | G15: 14 | H15: =F15*G15 -> 6440 | I15: 350 | J15: 950 | K15: =H15+I15-J15 -> 5840 | M15: 2850 | N15: 510 | O15: 350 | Q15: =K15/M15 -> 2.0491228 | R15: =K15/N15 -> 11.45098 | S15: =H15/O15 -> 18.4
D16: Isgec Heavy Engineering | E16: ISGEC | F16: 1050 | G16: 36 | H16: =F16*G16 -> 37800 | I16: 15000 | J16: 8500 | K16: =H16+I16-J16 -> 44300 | M16: 37500 | N16: 4500 | O16: 3100 | Q16: =K16/M16 -> 1.1813333 | R16: =K16/N16 -> 9.8444444 | S16: =H16/O16 -> 12.193548
D17: Grindwell Norton Ltd | E17: GRINDWEL | F17: 1820 | G17: 78 | H17: =F17*G17 -> 141960 | I17: 0 | J17: 11500 | K17: =H17+I17-J17 -> 130460 | M17: 24000 | N17: 5100 | O17: 3950 | Q17: =K17/M17 -> 5.4358333 | R17: =K17/N17 -> 25.580392 | S17: =H17/O17 -> 35.939241
D19: Average | Q19: =AVERAGE(Q8:Q17) -> 4.5017681 | R19: =AVERAGE(R8:R17) -> 24.004057 | S19: =AVERAGE(S8:S17) -> 33.951219
D20: Median | Q20: =MEDIAN(Q8:Q17) -> 3.9021217 | R20: =MEDIAN(R8:R17) -> 22.358824 | S20: =MEDIAN(S8:S17) -> 30.370247
D22: KSB Limited | E22: KSB | F22: 972 | G22: 174 | H22: 16912.8 | I22: 42 | J22: 18340 | K22: -1385.2 | M22: 26957 | N22: 3714 | O22: 2559 | Q22: =IF(K22>0,H22/K22,"N/M") -> N/M | R22: =IF(AND(N22>0,K22>0),K22/N22,"N/M") -> N/M | S22: =IF(O22>0,H22/O22,"N/M") -> 6.6091442
D24: Metric | E24: Comp | F24: Key Metric | G24: EV | H24: Net Debt (Debt−Cash) | I24: Equity Value (EV−Debt+Cash) | J24: Share | K24: Share Price
E25: X | G25: MM | H25: MM | I25: MM | J25: Crs
D27: EV/Revenue | E27: 4.746985 | F27: =M22 -> 26957 | G27: =F27*E27 -> 127964.47 | H27: -18298 | I27: 146262 | J27: =G22 -> 174 | K27: =I27/J27 -> 840.58621
D28: EV/EBITDA | E28: 25.308727 | F28: =N22 -> 3714 | G28: =E28*F28 -> 93996.611 | H28: -18298 | I28: 112295 | J28: =G22 -> 174 | K28: =I28/J28 -> 645.37356
D29: P/E | E29: 35.703225 | F29: =O22 -> 2559 | G29: =I29+-H29 -> 109655 | H29: -18298 | I29: 91357 | J29: =J28 -> 174 | K29: =I29/J29 -> 525.04023
D30: Current Market Price | K30: 972

Sheet WACC
A1: KSB LTD
A2: Weighted-Average Cost of Capital (WACC)
A4: Comparable Companies Beta
D7: Company | E7: Ticker | H7: Equity Value | I7: Total Debt | J7: Debt/Equity | K7: Debt/Capital | L7: Tax Rate | M7: Levered Beta | N7: Unlevered Beta
D9: Kirloskar Brothers Ltd | E9: KIRLOSBROS | H9: ='Comp Valuation'!H8 -> 102950 | I9: ='Comp Valuation'!I8 -> 2850 | J9: =I9/H9 -> 0.027683341 | K9: =I9/(H9+I9) -> 0.026937618 | L9: 0.275 | M9: 0.85 | N9: =M9/(1+J9*(1-L9)) -> 0.8332758
D10: Elgi Equipments Ltd | E10: ELGIEQUIP | H10: ='Comp Valuation'!H9 -> 182700 | I10: ='Comp Valuation'!I9 -> 1200 | J10: =I10/H10 -> 0.0065681445 | K10: =I10/(H10+I10) -> 0.0065252855 | L10: 0.262 | M10: 0.8 | N10: =M10/(1+J10*(1-L10)) -> 0.79614087
D11: Cummins India Ltd | E11: CUMMINSIND | H11: ='Comp Valuation'!H10 -> 695270 | I11: ='Comp Valuation'!I10 -> 2100 | J11: =I11/H11 -> 0.0030204093 | K11: =I11/(H11+I11) -> 0.0030113139 | L11: 0.248 | M11: 0.75 | N11: =M11/(1+J11*(1-L11)) -> 0.74830035
D12: Triveni Turbine Ltd | E12: TRITURBINE | H12: ='Comp Valuation'!H11 -> 204600 | I12: ='Comp Valuation'!I11 -> 800 | J12: =I12/H12 -> 0.0039100684 | K12: =I12/(H12+I12) -> 0.0038948393 | L12: 0.253 | M12: 0.9 | N12: =M12/(1+J12*(1-L12)) -> 0.89737892
D13: Ingersoll Rand India | E13: INGERRAND | H13: ='Comp Valuation'!H12 -> 110200 | I13: ='Comp Valuation'!I12 -> 0 | J13: =I13/H13 -> 0 | K13: =I13/(H13+I13) -> 0 | L13: 0.256 | M13: 0.7 | N13: =M13/(1+J13*(1-L13)) -> 0.7
D14: Shakti Pumps India Ltd | E14: SHAKTIPUMP | H14: ='Comp Valuation'!H13 -> 28350 | I14: ='Comp Valuation'!I13 -> 3200 | J14: =I14/H14 -> 0.11287478 | K14: =I14/(H14+I14) -> 0.10142631 | L14: 0.245 | M14: 1.1 | N14: =M14/(1+J14*(1-L14)) -> 1.0136189
D15: WPIL Ltd | E15: WPIL | H15: ='Comp Valuation'!H14 -> 7980 | I15: ='Comp Valuation'!I14 -> 1800 | J15: =I15/H15 -> 0.22556391 | K15: =I15/(H15+I15) -> 0.18404908 | L15: 0.281 | M15: 0.95 | N15: =M15/(1+J15*(1-L15)) -> 0.817429
D16: Roto Pumps Ltd | E16: ROTOPUMPS | H16: ='Comp Valuation'!H15 -> 6440 | I16: ='Comp Valuation'!I15 -> 350 | J16: =I16/H16 -> 0.054347826 | K16: =I16/(H16+I16) -> 0.051546392 | L16: 0.269 | M16: 0.85 | N16: =M16/(1+J16*(1-L16)) -> 0.8175213
D17: Isgec Heavy Engineering | E17: ISGEC | H17: ='Comp Valuation'!H16 -> 37800 | I17: ='Comp Valuation'!I16 -> 15000 | J17: =I17/H17 -> 0.3968254 | K17: =I17/(H17+I17) -> 0.28409091 | L17: 0.292 | M17: 1.05 | N17: =M17/(1+J17*(1-L17)) -> 0.8197026
D18: Grindwell Norton Ltd | E18: GRINDWELL | H18: ='Comp Valuation'!H17 -> 141960 | I18: ='Comp Valuation'!I17 -> 0 | J18: =I18/H18 -> 0 | K18: =I18/(H18+I18) -> 0 | L18: 0.247 | M18: 0.75 | N18: =M18/(1+J18*(1-L18)) -> 0.75
D20: Average | J20: =AVERAGE(J9:J18) -> 0.083079388 | K20: =AVERAGE(K9:K18) -> 0.066148174 | L20: =AVERAGE(L9:L18) -> 0.2628 | M20: =AVERAGE(M9:M18) -> 0.87 | N20: =AVERAGE(N9:N18) -> 0.81933678
D21: Median | J21: =MEDIAN(J9:J18) -> 0.017125743 | K21: =MEDIAN(K9:K18) -> 0.016731452 | L21: =MEDIAN(L9:L18) -> 0.259 | M21: =MEDIAN(M9:M18) -> 0.85 | N21: =MEDIAN(N9:N18) -> 0.81747515
D23: KSB Limited | E23: KSB | F23: Source: NSE/BSE | H23: 16913 | I23: 42 | J23: =I23/H23 -> 0.0024832969 | K23: 0.029828486 | L23: 0.25 | M23: 0.83748848
D25: WACC Calculation
D27: Total Capital Structure
D29: Proportion of debt | E29: =J20 -> 0.083079388
D30: Proportion of Equity | E30: =1-E29 -> 0.91692061
D31: Current Capital Structure
D32: Market Cap | E32: =H23 -> 16913
D33: Total Debt | E33: =I23 -> 42 | F33: ← Lease Liabilities only per Annual Report (no bank borrowings). Screener shows 520 incorrectly.
D34: Debt/Equity | E34: =J23 -> 0.0024832969
D36: Cost Of Debt
D37: Pre-tax Cost of Debt | E37: 0.075
D38: Tax Rate | E38: =L23 -> 0.25
D39: After-Tax Cost of Debt | E39: =E37*(1-E38) -> 0.05625
D41: Cost Of Equity
D42: Risk Free Rate | E42: 0.071
D43: Equity Market Return | E43: 0.133
D44: Equity Risk Premium | E44: =E43-E42 -> 0.062
D45: Levered Equity Beta | E45: =N21*(1+E34*(1-E38)) -> 0.81899767
D46: Cost of Equity | E46: =E42+(E44*E45) -> 0.12177786
D48: WACC | E48: =E29*E39+E46*E30 -> 0.11633384

Sheet Beta
A1: KSB Limited
A2: Company Beta — 5 Year Monthly Returns (Apr 2021 – Apr 2026)
A4: Month | B4: Index Close Price (Nifty 50) | C4: % Change Monthly | D4: Stock Close Price (KSB) | E4: % Change Monthly
A5: Apr-21 | B5: 14631.1 | D5: 1123
A6: May-21 | B6: 15582.8 | C6: =B6/B5-1 -> 0.065046374 | D6: 1187 | E6: =D6/D5-1 -> 0.056990205 | G6: Max | H6: =MAX(D53:D65) -> 4445
A7: Jun-21 | B7: 15721.5 | C7: =B7/B6-1 -> 0.0089008394 | D7: 1298 | E7: =D7/D6-1 -> 0.093513058 | G7: Min | H7: =MIN(D53:D65) -> 3867
A8: Jul-21 | B8: 16118.2 | C8: =B8/B7-1 -> 0.025232961 | D8: 1455 | E8: =D8/D7-1 -> 0.12095532
A9: Aug-21 | B9: 17132.2 | C9: =B9/B8-1 -> 0.062910251 | D9: 1568 | E9: =D9/D8-1 -> 0.07766323
A10: Sep-21 | B10: 17618.15 | C10: =B10/B9-1 -> 0.028364717 | D10: 1735 | E10: =D10/D9-1 -> 0.1065051 | G10: Beta | H10: =SLOPE(E6:E65,C6:C65) -> 1.4909927
A11: Oct-21 | B11: 18477.05 | C11: =B11/B10-1 -> 0.048750862 | D11: 1890 | E11: =D11/D10-1 -> 0.089337176
A12: Nov-21 | B12: 17026.45 | C12: =B12/B11-1 -> -0.078508203 | D12: 1812 | E12: =D12/D11-1 -> -0.041269841
A13: Dec-21 | B13: 17354.05 | C13: =B13/B12-1 -> 0.019240652 | D13: 1956 | E13: =D13/D12-1 -> 0.079470199
A14: Jan-22 | B14: 17339.85 | C14: =B14/B13-1 -> -0.0008182528 | D14: 2043 | E14: =D14/D13-1 -> 0.044478528
A15: Feb-22 | B15: 16793.9 | C15: =B15/B14-1 -> -0.031485278 | D15: 1987 | E15: =D15/D14-1 -> -0.027410671
A16: Mar-22 | B16: 17464.75 | C16: =B16/B15-1 -> 0.039946052 | D16: 2089 | E16: =D16/D15-1 -> 0.051333669
A17: Apr-22 | B17: 17102.55 | C17: =B17/B16-1 -> -0.020738917 | D17: 1980 | E17: =D17/D16-1 -> -0.052178076
A18: May-22 | B18: 16584.3 | C18: =B18/B17-1 -> -0.030302499 | D18: 1845 | E18: =D18/D17-1 -> -0.068181818
A19: Jun-22 | B19: 15780.25 | C19: =B19/B18-1 -> -0.048482601 | D19: 1678 | E19: =D19/D18-1 -> -0.090514905
A20: Jul-22 | B20: 17158.25 | C20: =B20/B19-1 -> 0.087324345 | D20: 1923 | E20: =D20/D19-1 -> 0.14600715
A21: Aug-22 | B21: 17759.3 | C21: =B21/B20-1 -> 0.035029796 | D21: 2105 | E21: =D21/D20-1 -> 0.094643786
A22: Sep-22 | B22: 17094.35 | C22: =B22/B21-1 -> -0.037442354 | D22: 2012 | E22: =D22/D21-1 -> -0.044180523
... A65: Apr-26 | B65: 24955.5 | C65: =B65/B64-1 -> 0.014876147 | D65: 4156 | E65: =D65/D64-1 -> 0.016385424

Sheet Summary
A1: KSB LTD
A2: Valuation Summary — Football Field
A4: Football Field Data
K5: Market
H6: Comp | I6: DCF | J6: 52-week hi/Lo | K6: Consenses
D7: High | H7: =MAX('Comp Valuation'!K27:K29) -> 840.58621 | I7: 746.89767 | J7: =Beta!H6/10 -> 444.5 | K7: 972
D8: High | H8: =H7 -> 840.58621 | I8: =I7 -> 746.89767 | J8: =J7 -> 444.5 | K8: 972
D9: Low | H9: =MIN('Comp Valuation'!K27:K29) -> 525.04023 | I9: 594.11576 | J9: =Beta!H7/10 -> 386.7 | K9: 716
D10: Low | H10: =H9 -> 525.04023 | I10: =I9 -> 594.11576 | J10: =J9 -> 386.7 | K10: 716
A12: Valuation Summary Chart
